<?xml version="1.0" ?>
<robot name="pendulum" xmlns:xacro="http://ros.org/wiki/xacro">
  <link name="base_link"/>
  <link name="link_1">
    <visual>
      <origin rpy="0 0 0" xyz="0 0 0.5"/>
      <geometry>
        <cylinder length="1.0" radius="0.05"/>
      </geometry>
      <material name="">
        <color rgba="0.95 0.95 0.95 1.0"/>
      </material>
    </visual>
  </link>
  <link name="link_2">
    <visual>
      <origin rpy="0 0 0" xyz="0 0 1.0"/>
      <geometry>
        <sphere radius="0.2"/>
      </geometry>
      <material name="">
        <color rgba="0.96 0.1 0.13 1.0"/>
      </material>
    </visual>
  </link>
  <joint name="joint_1" type="revolute">
    <origin rpy="0 0 0" xyz="0 0 0"/>
    <parent link="base_link"/>
    <child link="link_1"/>
    <axis xyz="1 0 0"/>
    <limit effort="0" lower="-6.28" upper="6.28" velocity="10.47"/>
  </joint>
  <joint name="joint_2" type="fixed">
    <origin rpy="0 0 0" xyz="0 0 0"/>
    <parent link="link_1"/>
    <child link="link_2"/>
  </joint>
</robot>
